candle closed at 11.80940000
mfi: 36.85516928149985, rsi: 52.96493372221297.
Unhandled Error
Traceback (most recent call last):
  File "C:\Users\Gebruiker\AppData\Local\Programs\Python\Python36\lib\site-packages\twisted\python\log.py", line 103, in callWithLogger
    return callWithContext({"system": lp}, func, *args, **kw)
  File "C:\Users\Gebruiker\AppData\Local\Programs\Python\Python36\lib\site-packages\twisted\python\log.py", line 86, in callWithContext
    return context.call({ILogContext: newCtx}, func, *args, **kw)
  File "C:\Users\Gebruiker\AppData\Local\Programs\Python\Python36\lib\site-packages\twisted\python\context.py", line 122, in callWithContext
    return self.currentContext().callWithContext(ctx, func, *args, **kw)
  File "C:\Users\Gebruiker\AppData\Local\Programs\Python\Python36\lib\site-packages\twisted\python\context.py", line 85, in callWithContext
    return func(*args,**kw)
--- <exception caught here> ---
  File "C:\Users\Gebruiker\AppData\Local\Programs\Python\Python36\lib\site-packages\twisted\internet\selectreactor.py", line 149, in _doReadOrWrite
    why = getattr(selectable, method)()
  File "C:\Users\Gebruiker\AppData\Local\Programs\Python\Python36\lib\site-packages\twisted\internet\tcp.py", line 243, in doRead
    return self._dataReceived(data)
  File "C:\Users\Gebruiker\AppData\Local\Programs\Python\Python36\lib\site-packages\twisted\internet\tcp.py", line 249, in _dataReceived
    rval = self.protocol.dataReceived(data)
  File "C:\Users\Gebruiker\AppData\Local\Programs\Python\Python36\lib\site-packages\twisted\protocols\tls.py", line 330, in dataReceived
    self._flushReceiveBIO()
  File "C:\Users\Gebruiker\AppData\Local\Programs\Python\Python36\lib\site-packages\twisted\protocols\tls.py", line 295, in _flushReceiveBIO
    ProtocolWrapper.dataReceived(self, bytes)
  File "C:\Users\Gebruiker\AppData\Local\Programs\Python\Python36\lib\site-packages\twisted\protocols\policies.py", line 120, in dataReceived
    self.wrappedProtocol.dataReceived(data)
  File "C:\Users\Gebruiker\AppData\Local\Programs\Python\Python36\lib\site-packages\autobahn\twisted\websocket.py", line 290, in dataReceived
    self._dataReceived(data)
  File "C:\Users\Gebruiker\AppData\Local\Programs\Python\Python36\lib\site-packages\autobahn\websocket\protocol.py", line 1207, in _dataReceived
    self.consumeData()
  File "C:\Users\Gebruiker\AppData\Local\Programs\Python\Python36\lib\site-packages\autobahn\websocket\protocol.py", line 1219, in consumeData
    while self.processData() and self.state != WebSocketProtocol.STATE_CLOSED:
  File "C:\Users\Gebruiker\AppData\Local\Programs\Python\Python36\lib\site-packages\autobahn\websocket\protocol.py", line 1579, in processData
    fr = self.onFrameEnd()
  File "C:\Users\Gebruiker\AppData\Local\Programs\Python\Python36\lib\site-packages\autobahn\websocket\protocol.py", line 1704, in onFrameEnd
    self._onMessageEnd()
  File "C:\Users\Gebruiker\AppData\Local\Programs\Python\Python36\lib\site-packages\autobahn\twisted\websocket.py", line 318, in _onMessageEnd
    self.onMessageEnd()
  File "C:\Users\Gebruiker\AppData\Local\Programs\Python\Python36\lib\site-packages\autobahn\websocket\protocol.py", line 628, in onMessageEnd
    self._onMessage(payload, self.message_is_binary)
  File "C:\Users\Gebruiker\AppData\Local\Programs\Python\Python36\lib\site-packages\autobahn\twisted\websocket.py", line 321, in _onMessage
    self.onMessage(payload, isBinary)
  File "C:\Users\Gebruiker\AppData\Local\Programs\Python\Python36\lib\site-packages\binance\websockets.py", line 31, in onMessage
    self.factory.callback(payload_obj)
  File "d:/AAA_personal_projects/AAA_repos/CryptoBot/BacktestSingleSocket.py", line 164, in process_message
    if order_succeeded:
builtins.UnboundLocalError: local variable 'order_succeeded' referenced before assignment

candle closed at 11.82730000
mfi: 42.9670402175117, rsi: 56.42238808642607.
Unhandled Error
Traceback (most recent call last):
  File "C:\Users\Gebruiker\AppData\Local\Programs\Python\Python36\lib\site-packages\twisted\python\log.py", line 103, in callWithLogger
    return callWithContext({"system": lp}, func, *args, **kw)
  File "C:\Users\Gebruiker\AppData\Local\Programs\Python\Python36\lib\site-packages\twisted\python\log.py", line 86, in callWithContext
    return context.call({ILogContext: newCtx}, func, *args, **kw)
  File "C:\Users\Gebruiker\AppData\Local\Programs\Python\Python36\lib\site-packages\twisted\python\context.py", line 122, in callWithContext
    return self.currentContext().callWithContext(ctx, func, *args, **kw)
  File "C:\Users\Gebruiker\AppData\Local\Programs\Python\Python36\lib\site-packages\twisted\python\context.py", line 85, in callWithContext
    return func(*args,**kw)
--- <exception caught here> ---
  File "C:\Users\Gebruiker\AppData\Local\Programs\Python\Python36\lib\site-packages\twisted\internet\selectreactor.py", line 149, in _doReadOrWrite
    why = getattr(selectable, method)()
  File "C:\Users\Gebruiker\AppData\Local\Programs\Python\Python36\lib\site-packages\twisted\internet\tcp.py", line 243, in doRead
    return self._dataReceived(data)
  File "C:\Users\Gebruiker\AppData\Local\Programs\Python\Python36\lib\site-packages\twisted\internet\tcp.py", line 249, in _dataReceived
    rval = self.protocol.dataReceived(data)
  File "C:\Users\Gebruiker\AppData\Local\Programs\Python\Python36\lib\site-packages\twisted\protocols\tls.py", line 330, in dataReceived
    self._flushReceiveBIO()
  File "C:\Users\Gebruiker\AppData\Local\Programs\Python\Python36\lib\site-packages\twisted\protocols\tls.py", line 295, in _flushReceiveBIO
    ProtocolWrapper.dataReceived(self, bytes)
  File "C:\Users\Gebruiker\AppData\Local\Programs\Python\Python36\lib\site-packages\twisted\protocols\policies.py", line 120, in dataReceived
    self.wrappedProtocol.dataReceived(data)
  File "C:\Users\Gebruiker\AppData\Local\Programs\Python\Python36\lib\site-packages\autobahn\twisted\websocket.py", line 290, in dataReceived
    self._dataReceived(data)
  File "C:\Users\Gebruiker\AppData\Local\Programs\Python\Python36\lib\site-packages\autobahn\websocket\protocol.py", line 1207, in _dataReceived
    self.consumeData()
  File "C:\Users\Gebruiker\AppData\Local\Programs\Python\Python36\lib\site-packages\autobahn\websocket\protocol.py", line 1219, in consumeData
    while self.processData() and self.state != WebSocketProtocol.STATE_CLOSED:
  File "C:\Users\Gebruiker\AppData\Local\Programs\Python\Python36\lib\site-packages\autobahn\websocket\protocol.py", line 1579, in processData
    fr = self.onFrameEnd()
  File "C:\Users\Gebruiker\AppData\Local\Programs\Python\Python36\lib\site-packages\autobahn\websocket\protocol.py", line 1704, in onFrameEnd
    self._onMessageEnd()
  File "C:\Users\Gebruiker\AppData\Local\Programs\Python\Python36\lib\site-packages\autobahn\twisted\websocket.py", line 318, in _onMessageEnd
    self.onMessageEnd()
  File "C:\Users\Gebruiker\AppData\Local\Programs\Python\Python36\lib\site-packages\autobahn\websocket\protocol.py", line 628, in onMessageEnd
    self._onMessage(payload, self.message_is_binary)
  File "C:\Users\Gebruiker\AppData\Local\Programs\Python\Python36\lib\site-packages\autobahn\twisted\websocket.py", line 321, in _onMessage
    self.onMessage(payload, isBinary)
  File "C:\Users\Gebruiker\AppData\Local\Programs\Python\Python36\lib\site-packages\binance\websockets.py", line 31, in onMessage
    self.factory.callback(payload_obj)
  File "d:/AAA_personal_projects/AAA_repos/CryptoBot/BacktestSingleSocket.py", line 164, in process_message
    if order_succeeded:
builtins.UnboundLocalError: local variable 'order_succeeded' referenced before assignment